INFO:daphne.server:HTTP/2 support not enabled (install the http2 and tls Twisted extras)
INFO:daphne.server:Using busy-loop synchronous mode on channel layer
INFO:daphne.server:Listening on endpoint tcp:port=8000:interface=127.0.0.1
INFO:daphne.server:HTTP/2 support not enabled (install the http2 and tls Twisted extras)
INFO:daphne.server:Using busy-loop synchronous mode on channel layer
INFO:daphne.server:Listening on endpoint tcp:port=8000:interface=127.0.0.1
INFO:daphne.server:HTTP/2 support not enabled (install the http2 and tls Twisted extras)
INFO:daphne.server:Using busy-loop synchronous mode on channel layer
INFO:daphne.server:Listening on endpoint tcp:port=8000:interface=127.0.0.1
INFO:daphne.server:HTTP/2 support not enabled (install the http2 and tls Twisted extras)
INFO:daphne.server:Using busy-loop synchronous mode on channel layer
INFO:daphne.server:Listening on endpoint tcp:port=8000:interface=127.0.0.1
INFO:root:the user amit has connected
INFO:daphne.server:HTTP/2 support not enabled (install the http2 and tls Twisted extras)
INFO:daphne.server:Using busy-loop synchronous mode on channel layer
INFO:daphne.server:Listening on endpoint tcp:port=8000:interface=127.0.0.1
WARNING:django.request:Not Found: /portal/
INFO:root:the user amit has connected
INFO:root:the user dan has connected
INFO:daphne.server:HTTP/2 support not enabled (install the http2 and tls Twisted extras)
INFO:daphne.server:Using busy-loop synchronous mode on channel layer
INFO:daphne.server:Listening on endpoint tcp:port=8000:interface=127.0.0.1
INFO:root:the user dan has connected
INFO:root:the user dan has connected
INFO:daphne.server:HTTP/2 support not enabled (install the http2 and tls Twisted extras)
INFO:daphne.server:Using busy-loop synchronous mode on channel layer
INFO:daphne.server:Listening on endpoint tcp:port=8000:interface=127.0.0.1
INFO:root:the user dan has connected
INFO:daphne.server:Using busy-loop synchronous mode on channel layer
INFO:daphne.server:Listening on endpoint tcp:port=8000:interface=127.0.0.1
ERROR:django.request:Internal Server Error: /
Traceback (most recent call last):
  File "/usr/local/lib/python3.5/dist-packages/django/core/handlers/exception.py", line 35, in inner
    response = get_response(request)
  File "/usr/local/lib/python3.5/dist-packages/django/core/handlers/base.py", line 158, in _get_response
    response = self.process_exception_by_middleware(e, request)
  File "/usr/local/lib/python3.5/dist-packages/channels/handler.py", line 243, in process_exception_by_middleware
    return super(AsgiHandler, self).process_exception_by_middleware(exception, request)
  File "/usr/local/lib/python3.5/dist-packages/django/core/handlers/base.py", line 156, in _get_response
    response = response.render()
  File "/usr/local/lib/python3.5/dist-packages/django/template/response.py", line 106, in render
    self.content = self.rendered_content
  File "/usr/local/lib/python3.5/dist-packages/django/template/response.py", line 83, in rendered_content
    content = template.render(context, self._request)
  File "/usr/local/lib/python3.5/dist-packages/django/template/backends/django.py", line 61, in render
    return self.template.render(context)
  File "/usr/local/lib/python3.5/dist-packages/django/template/base.py", line 175, in render
    return self._render(context)
  File "/usr/local/lib/python3.5/dist-packages/django/template/base.py", line 167, in _render
    return self.nodelist.render(context)
  File "/usr/local/lib/python3.5/dist-packages/django/template/base.py", line 943, in render
    bit = node.render_annotated(context)
  File "/usr/local/lib/python3.5/dist-packages/django/template/base.py", line 910, in render_annotated
    return self.render(context)
  File "/usr/local/lib/python3.5/dist-packages/django/template/loader_tags.py", line 155, in render
    return compiled_parent._render(context)
  File "/usr/local/lib/python3.5/dist-packages/django/template/base.py", line 167, in _render
    return self.nodelist.render(context)
  File "/usr/local/lib/python3.5/dist-packages/django/template/base.py", line 943, in render
    bit = node.render_annotated(context)
  File "/usr/local/lib/python3.5/dist-packages/django/template/base.py", line 910, in render_annotated
    return self.render(context)
  File "/usr/local/lib/python3.5/dist-packages/django/template/loader_tags.py", line 67, in render
    result = block.nodelist.render(context)
  File "/usr/local/lib/python3.5/dist-packages/django/template/base.py", line 943, in render
    bit = node.render_annotated(context)
  File "/usr/local/lib/python3.5/dist-packages/django/template/base.py", line 910, in render_annotated
    return self.render(context)
  File "/usr/local/lib/python3.5/dist-packages/django/template/defaulttags.py", line 167, in render
    values = list(values)
TypeError: 'ChatRoom' object is not iterable
ERROR:django.request:Internal Server Error: /
Traceback (most recent call last):
  File "/usr/local/lib/python3.5/dist-packages/django/core/handlers/exception.py", line 35, in inner
    response = get_response(request)
  File "/usr/local/lib/python3.5/dist-packages/django/core/handlers/base.py", line 158, in _get_response
    response = self.process_exception_by_middleware(e, request)
  File "/usr/local/lib/python3.5/dist-packages/channels/handler.py", line 243, in process_exception_by_middleware
    return super(AsgiHandler, self).process_exception_by_middleware(exception, request)
  File "/usr/local/lib/python3.5/dist-packages/django/core/handlers/base.py", line 156, in _get_response
    response = response.render()
  File "/usr/local/lib/python3.5/dist-packages/django/template/response.py", line 106, in render
    self.content = self.rendered_content
  File "/usr/local/lib/python3.5/dist-packages/django/template/response.py", line 83, in rendered_content
    content = template.render(context, self._request)
  File "/usr/local/lib/python3.5/dist-packages/django/template/backends/django.py", line 61, in render
    return self.template.render(context)
  File "/usr/local/lib/python3.5/dist-packages/django/template/base.py", line 175, in render
    return self._render(context)
  File "/usr/local/lib/python3.5/dist-packages/django/template/base.py", line 167, in _render
    return self.nodelist.render(context)
  File "/usr/local/lib/python3.5/dist-packages/django/template/base.py", line 943, in render
    bit = node.render_annotated(context)
  File "/usr/local/lib/python3.5/dist-packages/django/template/base.py", line 910, in render_annotated
    return self.render(context)
  File "/usr/local/lib/python3.5/dist-packages/django/template/loader_tags.py", line 155, in render
    return compiled_parent._render(context)
  File "/usr/local/lib/python3.5/dist-packages/django/template/base.py", line 167, in _render
    return self.nodelist.render(context)
  File "/usr/local/lib/python3.5/dist-packages/django/template/base.py", line 943, in render
    bit = node.render_annotated(context)
  File "/usr/local/lib/python3.5/dist-packages/django/template/base.py", line 910, in render_annotated
    return self.render(context)
  File "/usr/local/lib/python3.5/dist-packages/django/template/loader_tags.py", line 67, in render
    result = block.nodelist.render(context)
  File "/usr/local/lib/python3.5/dist-packages/django/template/base.py", line 943, in render
    bit = node.render_annotated(context)
  File "/usr/local/lib/python3.5/dist-packages/django/template/base.py", line 910, in render_annotated
    return self.render(context)
  File "/usr/local/lib/python3.5/dist-packages/django/template/defaulttags.py", line 167, in render
    values = list(values)
TypeError: 'ChatRoom' object is not iterable
ERROR:django.request:Internal Server Error: /
Traceback (most recent call last):
  File "/usr/local/lib/python3.5/dist-packages/django/core/handlers/exception.py", line 35, in inner
    response = get_response(request)
  File "/usr/local/lib/python3.5/dist-packages/django/core/handlers/base.py", line 158, in _get_response
    response = self.process_exception_by_middleware(e, request)
  File "/usr/local/lib/python3.5/dist-packages/channels/handler.py", line 243, in process_exception_by_middleware
    return super(AsgiHandler, self).process_exception_by_middleware(exception, request)
  File "/usr/local/lib/python3.5/dist-packages/django/core/handlers/base.py", line 156, in _get_response
    response = response.render()
  File "/usr/local/lib/python3.5/dist-packages/django/template/response.py", line 106, in render
    self.content = self.rendered_content
  File "/usr/local/lib/python3.5/dist-packages/django/template/response.py", line 83, in rendered_content
    content = template.render(context, self._request)
  File "/usr/local/lib/python3.5/dist-packages/django/template/backends/django.py", line 61, in render
    return self.template.render(context)
  File "/usr/local/lib/python3.5/dist-packages/django/template/base.py", line 175, in render
    return self._render(context)
  File "/usr/local/lib/python3.5/dist-packages/django/template/base.py", line 167, in _render
    return self.nodelist.render(context)
  File "/usr/local/lib/python3.5/dist-packages/django/template/base.py", line 943, in render
    bit = node.render_annotated(context)
  File "/usr/local/lib/python3.5/dist-packages/django/template/base.py", line 910, in render_annotated
    return self.render(context)
  File "/usr/local/lib/python3.5/dist-packages/django/template/loader_tags.py", line 155, in render
    return compiled_parent._render(context)
  File "/usr/local/lib/python3.5/dist-packages/django/template/base.py", line 167, in _render
    return self.nodelist.render(context)
  File "/usr/local/lib/python3.5/dist-packages/django/template/base.py", line 943, in render
    bit = node.render_annotated(context)
  File "/usr/local/lib/python3.5/dist-packages/django/template/base.py", line 910, in render_annotated
    return self.render(context)
  File "/usr/local/lib/python3.5/dist-packages/django/template/loader_tags.py", line 67, in render
    result = block.nodelist.render(context)
  File "/usr/local/lib/python3.5/dist-packages/django/template/base.py", line 943, in render
    bit = node.render_annotated(context)
  File "/usr/local/lib/python3.5/dist-packages/django/template/base.py", line 910, in render_annotated
    return self.render(context)
  File "/usr/local/lib/python3.5/dist-packages/django/template/defaulttags.py", line 167, in render
    values = list(values)
TypeError: 'ChatRoom' object is not iterable
ERROR:django.request:Internal Server Error: /
Traceback (most recent call last):
  File "/usr/local/lib/python3.5/dist-packages/django/core/handlers/exception.py", line 35, in inner
    response = get_response(request)
  File "/usr/local/lib/python3.5/dist-packages/django/core/handlers/base.py", line 158, in _get_response
    response = self.process_exception_by_middleware(e, request)
  File "/usr/local/lib/python3.5/dist-packages/channels/handler.py", line 243, in process_exception_by_middleware
    return super(AsgiHandler, self).process_exception_by_middleware(exception, request)
  File "/usr/local/lib/python3.5/dist-packages/django/core/handlers/base.py", line 156, in _get_response
    response = response.render()
  File "/usr/local/lib/python3.5/dist-packages/django/template/response.py", line 106, in render
    self.content = self.rendered_content
  File "/usr/local/lib/python3.5/dist-packages/django/template/response.py", line 83, in rendered_content
    content = template.render(context, self._request)
  File "/usr/local/lib/python3.5/dist-packages/django/template/backends/django.py", line 61, in render
    return self.template.render(context)
  File "/usr/local/lib/python3.5/dist-packages/django/template/base.py", line 175, in render
    return self._render(context)
  File "/usr/local/lib/python3.5/dist-packages/django/template/base.py", line 167, in _render
    return self.nodelist.render(context)
  File "/usr/local/lib/python3.5/dist-packages/django/template/base.py", line 943, in render
    bit = node.render_annotated(context)
  File "/usr/local/lib/python3.5/dist-packages/django/template/base.py", line 910, in render_annotated
    return self.render(context)
  File "/usr/local/lib/python3.5/dist-packages/django/template/loader_tags.py", line 155, in render
    return compiled_parent._render(context)
  File "/usr/local/lib/python3.5/dist-packages/django/template/base.py", line 167, in _render
    return self.nodelist.render(context)
  File "/usr/local/lib/python3.5/dist-packages/django/template/base.py", line 943, in render
    bit = node.render_annotated(context)
  File "/usr/local/lib/python3.5/dist-packages/django/template/base.py", line 910, in render_annotated
    return self.render(context)
  File "/usr/local/lib/python3.5/dist-packages/django/template/loader_tags.py", line 67, in render
    result = block.nodelist.render(context)
  File "/usr/local/lib/python3.5/dist-packages/django/template/base.py", line 943, in render
    bit = node.render_annotated(context)
  File "/usr/local/lib/python3.5/dist-packages/django/template/base.py", line 910, in render_annotated
    return self.render(context)
  File "/usr/local/lib/python3.5/dist-packages/django/template/defaulttags.py", line 167, in render
    values = list(values)
TypeError: 'int' object is not iterable
ERROR:django.request:Internal Server Error: /
Traceback (most recent call last):
  File "/usr/local/lib/python3.5/dist-packages/django/core/handlers/exception.py", line 35, in inner
    response = get_response(request)
  File "/usr/local/lib/python3.5/dist-packages/django/core/handlers/base.py", line 158, in _get_response
    response = self.process_exception_by_middleware(e, request)
  File "/usr/local/lib/python3.5/dist-packages/channels/handler.py", line 243, in process_exception_by_middleware
    return super(AsgiHandler, self).process_exception_by_middleware(exception, request)
  File "/usr/local/lib/python3.5/dist-packages/django/core/handlers/base.py", line 156, in _get_response
    response = response.render()
  File "/usr/local/lib/python3.5/dist-packages/django/template/response.py", line 106, in render
    self.content = self.rendered_content
  File "/usr/local/lib/python3.5/dist-packages/django/template/response.py", line 81, in rendered_content
    template = self.resolve_template(self.template_name)
  File "/usr/local/lib/python3.5/dist-packages/django/template/response.py", line 63, in resolve_template
    return select_template(template, using=self.using)
  File "/usr/local/lib/python3.5/dist-packages/django/template/loader.py", line 42, in select_template
    return engine.get_template(template_name)
  File "/usr/local/lib/python3.5/dist-packages/django/template/backends/django.py", line 34, in get_template
    return Template(self.engine.get_template(template_name), self)
  File "/usr/local/lib/python3.5/dist-packages/django/template/engine.py", line 144, in get_template
    template, origin = self.find_template(template_name)
  File "/usr/local/lib/python3.5/dist-packages/django/template/engine.py", line 126, in find_template
    template = loader.get_template(name, skip=skip)
  File "/usr/local/lib/python3.5/dist-packages/django/template/loaders/base.py", line 30, in get_template
    contents, origin, origin.template_name, self.engine,
  File "/usr/local/lib/python3.5/dist-packages/django/template/base.py", line 160, in __init__
    self.nodelist = self.compile_nodelist()
  File "/usr/local/lib/python3.5/dist-packages/django/template/base.py", line 198, in compile_nodelist
    return parser.parse()
  File "/usr/local/lib/python3.5/dist-packages/django/template/base.py", line 483, in parse
    raise self.error(token, e)
  File "/usr/local/lib/python3.5/dist-packages/django/template/base.py", line 481, in parse
    compiled_result = compile_func(self, token)
  File "/usr/local/lib/python3.5/dist-packages/django/template/loader_tags.py", line 290, in do_extends
    nodelist = parser.parse()
  File "/usr/local/lib/python3.5/dist-packages/django/template/base.py", line 483, in parse
    raise self.error(token, e)
  File "/usr/local/lib/python3.5/dist-packages/django/template/base.py", line 481, in parse
    compiled_result = compile_func(self, token)
  File "/usr/local/lib/python3.5/dist-packages/django/template/loader_tags.py", line 233, in do_block
    nodelist = parser.parse(('endblock',))
  File "/usr/local/lib/python3.5/dist-packages/django/template/base.py", line 483, in parse
    raise self.error(token, e)
  File "/usr/local/lib/python3.5/dist-packages/django/template/base.py", line 481, in parse
    compiled_result = compile_func(self, token)
  File "/usr/local/lib/python3.5/dist-packages/django/template/defaulttags.py", line 814, in do_for
    sequence = parser.compile_filter(bits[in_index + 1])
  File "/usr/local/lib/python3.5/dist-packages/django/template/base.py", line 568, in compile_filter
    return FilterExpression(token, self)
  File "/usr/local/lib/python3.5/dist-packages/django/template/base.py", line 668, in __init__
    "from '%s'" % (token[upto:], token))
django.template.exceptions.TemplateSyntaxError: Could not parse the remainder: '[1,2,3]' from '[1,2,3]'
ERROR:django.request:Internal Server Error: /
Traceback (most recent call last):
  File "/usr/local/lib/python3.5/dist-packages/django/core/handlers/exception.py", line 35, in inner
    response = get_response(request)
  File "/usr/local/lib/python3.5/dist-packages/django/core/handlers/base.py", line 158, in _get_response
    response = self.process_exception_by_middleware(e, request)
  File "/usr/local/lib/python3.5/dist-packages/channels/handler.py", line 243, in process_exception_by_middleware
    return super(AsgiHandler, self).process_exception_by_middleware(exception, request)
  File "/usr/local/lib/python3.5/dist-packages/django/core/handlers/base.py", line 156, in _get_response
    response = response.render()
  File "/usr/local/lib/python3.5/dist-packages/django/template/response.py", line 106, in render
    self.content = self.rendered_content
  File "/usr/local/lib/python3.5/dist-packages/django/template/response.py", line 83, in rendered_content
    content = template.render(context, self._request)
  File "/usr/local/lib/python3.5/dist-packages/django/template/backends/django.py", line 61, in render
    return self.template.render(context)
  File "/usr/local/lib/python3.5/dist-packages/django/template/base.py", line 175, in render
    return self._render(context)
  File "/usr/local/lib/python3.5/dist-packages/django/template/base.py", line 167, in _render
    return self.nodelist.render(context)
  File "/usr/local/lib/python3.5/dist-packages/django/template/base.py", line 943, in render
    bit = node.render_annotated(context)
  File "/usr/local/lib/python3.5/dist-packages/django/template/base.py", line 910, in render_annotated
    return self.render(context)
  File "/usr/local/lib/python3.5/dist-packages/django/template/loader_tags.py", line 155, in render
    return compiled_parent._render(context)
  File "/usr/local/lib/python3.5/dist-packages/django/template/base.py", line 167, in _render
    return self.nodelist.render(context)
  File "/usr/local/lib/python3.5/dist-packages/django/template/base.py", line 943, in render
    bit = node.render_annotated(context)
  File "/usr/local/lib/python3.5/dist-packages/django/template/base.py", line 910, in render_annotated
    return self.render(context)
  File "/usr/local/lib/python3.5/dist-packages/django/template/loader_tags.py", line 67, in render
    result = block.nodelist.render(context)
  File "/usr/local/lib/python3.5/dist-packages/django/template/base.py", line 943, in render
    bit = node.render_annotated(context)
  File "/usr/local/lib/python3.5/dist-packages/django/template/base.py", line 910, in render_annotated
    return self.render(context)
  File "/usr/local/lib/python3.5/dist-packages/django/template/defaulttags.py", line 167, in render
    values = list(values)
TypeError: 'int' object is not iterable
INFO:daphne.server:HTTP/2 support not enabled (install the http2 and tls Twisted extras)
INFO:daphne.server:Using busy-loop synchronous mode on channel layer
INFO:daphne.server:Listening on endpoint tcp:port=8000:interface=127.0.0.1
INFO:daphne.server:HTTP/2 support not enabled (install the http2 and tls Twisted extras)
INFO:daphne.server:Using busy-loop synchronous mode on channel layer
INFO:daphne.server:Listening on endpoint tcp:port=8000:interface=127.0.0.1
ERROR:django.request:Internal Server Error: /
Traceback (most recent call last):
  File "/usr/local/lib/python3.5/dist-packages/django/core/handlers/exception.py", line 35, in inner
    response = get_response(request)
  File "/usr/local/lib/python3.5/dist-packages/django/core/handlers/base.py", line 158, in _get_response
    response = self.process_exception_by_middleware(e, request)
  File "/usr/local/lib/python3.5/dist-packages/channels/handler.py", line 243, in process_exception_by_middleware
    return super(AsgiHandler, self).process_exception_by_middleware(exception, request)
  File "/usr/local/lib/python3.5/dist-packages/django/core/handlers/base.py", line 156, in _get_response
    response = response.render()
  File "/usr/local/lib/python3.5/dist-packages/django/template/response.py", line 106, in render
    self.content = self.rendered_content
  File "/usr/local/lib/python3.5/dist-packages/django/template/response.py", line 83, in rendered_content
    content = template.render(context, self._request)
  File "/usr/local/lib/python3.5/dist-packages/django/template/backends/django.py", line 61, in render
    return self.template.render(context)
  File "/usr/local/lib/python3.5/dist-packages/django/template/base.py", line 175, in render
    return self._render(context)
  File "/usr/local/lib/python3.5/dist-packages/django/template/base.py", line 167, in _render
    return self.nodelist.render(context)
  File "/usr/local/lib/python3.5/dist-packages/django/template/base.py", line 943, in render
    bit = node.render_annotated(context)
  File "/usr/local/lib/python3.5/dist-packages/django/template/base.py", line 910, in render_annotated
    return self.render(context)
  File "/usr/local/lib/python3.5/dist-packages/django/template/loader_tags.py", line 155, in render
    return compiled_parent._render(context)
  File "/usr/local/lib/python3.5/dist-packages/django/template/base.py", line 167, in _render
    return self.nodelist.render(context)
  File "/usr/local/lib/python3.5/dist-packages/django/template/base.py", line 943, in render
    bit = node.render_annotated(context)
  File "/usr/local/lib/python3.5/dist-packages/django/template/base.py", line 910, in render_annotated
    return self.render(context)
  File "/usr/local/lib/python3.5/dist-packages/django/template/loader_tags.py", line 67, in render
    result = block.nodelist.render(context)
  File "/usr/local/lib/python3.5/dist-packages/django/template/base.py", line 943, in render
    bit = node.render_annotated(context)
  File "/usr/local/lib/python3.5/dist-packages/django/template/base.py", line 910, in render_annotated
    return self.render(context)
  File "/usr/local/lib/python3.5/dist-packages/django/template/defaulttags.py", line 211, in render
    nodelist.append(node.render_annotated(context))
  File "/usr/local/lib/python3.5/dist-packages/django/template/base.py", line 910, in render_annotated
    return self.render(context)
  File "/usr/local/lib/python3.5/dist-packages/django/template/defaulttags.py", line 447, in render
    url = reverse(view_name, args=args, kwargs=kwargs, current_app=current_app)
  File "/usr/local/lib/python3.5/dist-packages/django/urls/base.py", line 88, in reverse
    return iri_to_uri(resolver._reverse_with_prefix(view, prefix, *args, **kwargs))
  File "/usr/local/lib/python3.5/dist-packages/django/urls/resolvers.py", line 632, in _reverse_with_prefix
    raise NoReverseMatch(msg)
django.urls.exceptions.NoReverseMatch: Reverse for 'single_room' with arguments '(3,)' not found. 1 pattern(s) tried: ['$(?P<pk>[0-9]+)']
ERROR:django.request:Internal Server Error: /
Traceback (most recent call last):
  File "/usr/local/lib/python3.5/dist-packages/django/core/handlers/exception.py", line 35, in inner
    response = get_response(request)
  File "/usr/local/lib/python3.5/dist-packages/django/core/handlers/base.py", line 158, in _get_response
    response = self.process_exception_by_middleware(e, request)
  File "/usr/local/lib/python3.5/dist-packages/channels/handler.py", line 243, in process_exception_by_middleware
    return super(AsgiHandler, self).process_exception_by_middleware(exception, request)
  File "/usr/local/lib/python3.5/dist-packages/django/core/handlers/base.py", line 156, in _get_response
    response = response.render()
  File "/usr/local/lib/python3.5/dist-packages/django/template/response.py", line 106, in render
    self.content = self.rendered_content
  File "/usr/local/lib/python3.5/dist-packages/django/template/response.py", line 83, in rendered_content
    content = template.render(context, self._request)
  File "/usr/local/lib/python3.5/dist-packages/django/template/backends/django.py", line 61, in render
    return self.template.render(context)
  File "/usr/local/lib/python3.5/dist-packages/django/template/base.py", line 175, in render
    return self._render(context)
  File "/usr/local/lib/python3.5/dist-packages/django/template/base.py", line 167, in _render
    return self.nodelist.render(context)
  File "/usr/local/lib/python3.5/dist-packages/django/template/base.py", line 943, in render
    bit = node.render_annotated(context)
  File "/usr/local/lib/python3.5/dist-packages/django/template/base.py", line 910, in render_annotated
    return self.render(context)
  File "/usr/local/lib/python3.5/dist-packages/django/template/loader_tags.py", line 155, in render
    return compiled_parent._render(context)
  File "/usr/local/lib/python3.5/dist-packages/django/template/base.py", line 167, in _render
    return self.nodelist.render(context)
  File "/usr/local/lib/python3.5/dist-packages/django/template/base.py", line 943, in render
    bit = node.render_annotated(context)
  File "/usr/local/lib/python3.5/dist-packages/django/template/base.py", line 910, in render_annotated
    return self.render(context)
  File "/usr/local/lib/python3.5/dist-packages/django/template/loader_tags.py", line 67, in render
    result = block.nodelist.render(context)
  File "/usr/local/lib/python3.5/dist-packages/django/template/base.py", line 943, in render
    bit = node.render_annotated(context)
  File "/usr/local/lib/python3.5/dist-packages/django/template/base.py", line 910, in render_annotated
    return self.render(context)
  File "/usr/local/lib/python3.5/dist-packages/django/template/defaulttags.py", line 211, in render
    nodelist.append(node.render_annotated(context))
  File "/usr/local/lib/python3.5/dist-packages/django/template/base.py", line 910, in render_annotated
    return self.render(context)
  File "/usr/local/lib/python3.5/dist-packages/django/template/defaulttags.py", line 447, in render
    url = reverse(view_name, args=args, kwargs=kwargs, current_app=current_app)
  File "/usr/local/lib/python3.5/dist-packages/django/urls/base.py", line 88, in reverse
    return iri_to_uri(resolver._reverse_with_prefix(view, prefix, *args, **kwargs))
  File "/usr/local/lib/python3.5/dist-packages/django/urls/resolvers.py", line 632, in _reverse_with_prefix
    raise NoReverseMatch(msg)
django.urls.exceptions.NoReverseMatch: Reverse for 'single_room' with arguments '(3,)' not found. 1 pattern(s) tried: ['$(?P<pk>[0-9]+)']
ERROR:django.request:Internal Server Error: /
Traceback (most recent call last):
  File "/usr/local/lib/python3.5/dist-packages/django/core/handlers/exception.py", line 35, in inner
    response = get_response(request)
  File "/usr/local/lib/python3.5/dist-packages/django/core/handlers/base.py", line 158, in _get_response
    response = self.process_exception_by_middleware(e, request)
  File "/usr/local/lib/python3.5/dist-packages/channels/handler.py", line 243, in process_exception_by_middleware
    return super(AsgiHandler, self).process_exception_by_middleware(exception, request)
  File "/usr/local/lib/python3.5/dist-packages/django/core/handlers/base.py", line 156, in _get_response
    response = response.render()
  File "/usr/local/lib/python3.5/dist-packages/django/template/response.py", line 106, in render
    self.content = self.rendered_content
  File "/usr/local/lib/python3.5/dist-packages/django/template/response.py", line 83, in rendered_content
    content = template.render(context, self._request)
  File "/usr/local/lib/python3.5/dist-packages/django/template/backends/django.py", line 61, in render
    return self.template.render(context)
  File "/usr/local/lib/python3.5/dist-packages/django/template/base.py", line 175, in render
    return self._render(context)
  File "/usr/local/lib/python3.5/dist-packages/django/template/base.py", line 167, in _render
    return self.nodelist.render(context)
  File "/usr/local/lib/python3.5/dist-packages/django/template/base.py", line 943, in render
    bit = node.render_annotated(context)
  File "/usr/local/lib/python3.5/dist-packages/django/template/base.py", line 910, in render_annotated
    return self.render(context)
  File "/usr/local/lib/python3.5/dist-packages/django/template/loader_tags.py", line 155, in render
    return compiled_parent._render(context)
  File "/usr/local/lib/python3.5/dist-packages/django/template/base.py", line 167, in _render
    return self.nodelist.render(context)
  File "/usr/local/lib/python3.5/dist-packages/django/template/base.py", line 943, in render
    bit = node.render_annotated(context)
  File "/usr/local/lib/python3.5/dist-packages/django/template/base.py", line 910, in render_annotated
    return self.render(context)
  File "/usr/local/lib/python3.5/dist-packages/django/template/loader_tags.py", line 67, in render
    result = block.nodelist.render(context)
  File "/usr/local/lib/python3.5/dist-packages/django/template/base.py", line 943, in render
    bit = node.render_annotated(context)
  File "/usr/local/lib/python3.5/dist-packages/django/template/base.py", line 910, in render_annotated
    return self.render(context)
  File "/usr/local/lib/python3.5/dist-packages/django/template/defaulttags.py", line 211, in render
    nodelist.append(node.render_annotated(context))
  File "/usr/local/lib/python3.5/dist-packages/django/template/base.py", line 910, in render_annotated
    return self.render(context)
  File "/usr/local/lib/python3.5/dist-packages/django/template/defaulttags.py", line 447, in render
    url = reverse(view_name, args=args, kwargs=kwargs, current_app=current_app)
  File "/usr/local/lib/python3.5/dist-packages/django/urls/base.py", line 88, in reverse
    return iri_to_uri(resolver._reverse_with_prefix(view, prefix, *args, **kwargs))
  File "/usr/local/lib/python3.5/dist-packages/django/urls/resolvers.py", line 632, in _reverse_with_prefix
    raise NoReverseMatch(msg)
django.urls.exceptions.NoReverseMatch: Reverse for 'single_room' with arguments '(3,)' not found. 1 pattern(s) tried: ['$(?P<pk>[0-9]+)']
ERROR:django.request:Internal Server Error: /
Traceback (most recent call last):
  File "/usr/local/lib/python3.5/dist-packages/django/core/handlers/exception.py", line 35, in inner
    response = get_response(request)
  File "/usr/local/lib/python3.5/dist-packages/django/core/handlers/base.py", line 158, in _get_response
    response = self.process_exception_by_middleware(e, request)
  File "/usr/local/lib/python3.5/dist-packages/channels/handler.py", line 243, in process_exception_by_middleware
    return super(AsgiHandler, self).process_exception_by_middleware(exception, request)
  File "/usr/local/lib/python3.5/dist-packages/django/core/handlers/base.py", line 156, in _get_response
    response = response.render()
  File "/usr/local/lib/python3.5/dist-packages/django/template/response.py", line 106, in render
    self.content = self.rendered_content
  File "/usr/local/lib/python3.5/dist-packages/django/template/response.py", line 83, in rendered_content
    content = template.render(context, self._request)
  File "/usr/local/lib/python3.5/dist-packages/django/template/backends/django.py", line 61, in render
    return self.template.render(context)
  File "/usr/local/lib/python3.5/dist-packages/django/template/base.py", line 175, in render
    return self._render(context)
  File "/usr/local/lib/python3.5/dist-packages/django/template/base.py", line 167, in _render
    return self.nodelist.render(context)
  File "/usr/local/lib/python3.5/dist-packages/django/template/base.py", line 943, in render
    bit = node.render_annotated(context)
  File "/usr/local/lib/python3.5/dist-packages/django/template/base.py", line 910, in render_annotated
    return self.render(context)
  File "/usr/local/lib/python3.5/dist-packages/django/template/loader_tags.py", line 155, in render
    return compiled_parent._render(context)
  File "/usr/local/lib/python3.5/dist-packages/django/template/base.py", line 167, in _render
    return self.nodelist.render(context)
  File "/usr/local/lib/python3.5/dist-packages/django/template/base.py", line 943, in render
    bit = node.render_annotated(context)
  File "/usr/local/lib/python3.5/dist-packages/django/template/base.py", line 910, in render_annotated
    return self.render(context)
  File "/usr/local/lib/python3.5/dist-packages/django/template/loader_tags.py", line 67, in render
    result = block.nodelist.render(context)
  File "/usr/local/lib/python3.5/dist-packages/django/template/base.py", line 943, in render
    bit = node.render_annotated(context)
  File "/usr/local/lib/python3.5/dist-packages/django/template/base.py", line 910, in render_annotated
    return self.render(context)
  File "/usr/local/lib/python3.5/dist-packages/django/template/defaulttags.py", line 211, in render
    nodelist.append(node.render_annotated(context))
  File "/usr/local/lib/python3.5/dist-packages/django/template/base.py", line 910, in render_annotated
    return self.render(context)
  File "/usr/local/lib/python3.5/dist-packages/django/template/defaulttags.py", line 447, in render
    url = reverse(view_name, args=args, kwargs=kwargs, current_app=current_app)
  File "/usr/local/lib/python3.5/dist-packages/django/urls/base.py", line 88, in reverse
    return iri_to_uri(resolver._reverse_with_prefix(view, prefix, *args, **kwargs))
  File "/usr/local/lib/python3.5/dist-packages/django/urls/resolvers.py", line 632, in _reverse_with_prefix
    raise NoReverseMatch(msg)
django.urls.exceptions.NoReverseMatch: Reverse for 'single_room' with arguments '(3,)' not found. 1 pattern(s) tried: ['$(?P<pk>[0-9]+)']
ERROR:django.request:Internal Server Error: /
Traceback (most recent call last):
  File "/usr/local/lib/python3.5/dist-packages/django/core/handlers/exception.py", line 35, in inner
    response = get_response(request)
  File "/usr/local/lib/python3.5/dist-packages/django/core/handlers/base.py", line 158, in _get_response
    response = self.process_exception_by_middleware(e, request)
  File "/usr/local/lib/python3.5/dist-packages/channels/handler.py", line 243, in process_exception_by_middleware
    return super(AsgiHandler, self).process_exception_by_middleware(exception, request)
  File "/usr/local/lib/python3.5/dist-packages/django/core/handlers/base.py", line 156, in _get_response
    response = response.render()
  File "/usr/local/lib/python3.5/dist-packages/django/template/response.py", line 106, in render
    self.content = self.rendered_content
  File "/usr/local/lib/python3.5/dist-packages/django/template/response.py", line 83, in rendered_content
    content = template.render(context, self._request)
  File "/usr/local/lib/python3.5/dist-packages/django/template/backends/django.py", line 61, in render
    return self.template.render(context)
  File "/usr/local/lib/python3.5/dist-packages/django/template/base.py", line 175, in render
    return self._render(context)
  File "/usr/local/lib/python3.5/dist-packages/django/template/base.py", line 167, in _render
    return self.nodelist.render(context)
  File "/usr/local/lib/python3.5/dist-packages/django/template/base.py", line 943, in render
    bit = node.render_annotated(context)
  File "/usr/local/lib/python3.5/dist-packages/django/template/base.py", line 910, in render_annotated
    return self.render(context)
  File "/usr/local/lib/python3.5/dist-packages/django/template/loader_tags.py", line 155, in render
    return compiled_parent._render(context)
  File "/usr/local/lib/python3.5/dist-packages/django/template/base.py", line 167, in _render
    return self.nodelist.render(context)
  File "/usr/local/lib/python3.5/dist-packages/django/template/base.py", line 943, in render
    bit = node.render_annotated(context)
  File "/usr/local/lib/python3.5/dist-packages/django/template/base.py", line 910, in render_annotated
    return self.render(context)
  File "/usr/local/lib/python3.5/dist-packages/django/template/loader_tags.py", line 67, in render
    result = block.nodelist.render(context)
  File "/usr/local/lib/python3.5/dist-packages/django/template/base.py", line 943, in render
    bit = node.render_annotated(context)
  File "/usr/local/lib/python3.5/dist-packages/django/template/base.py", line 910, in render_annotated
    return self.render(context)
  File "/usr/local/lib/python3.5/dist-packages/django/template/defaulttags.py", line 211, in render
    nodelist.append(node.render_annotated(context))
  File "/usr/local/lib/python3.5/dist-packages/django/template/base.py", line 910, in render_annotated
    return self.render(context)
  File "/usr/local/lib/python3.5/dist-packages/django/template/defaulttags.py", line 447, in render
    url = reverse(view_name, args=args, kwargs=kwargs, current_app=current_app)
  File "/usr/local/lib/python3.5/dist-packages/django/urls/base.py", line 88, in reverse
    return iri_to_uri(resolver._reverse_with_prefix(view, prefix, *args, **kwargs))
  File "/usr/local/lib/python3.5/dist-packages/django/urls/resolvers.py", line 632, in _reverse_with_prefix
    raise NoReverseMatch(msg)
django.urls.exceptions.NoReverseMatch: Reverse for 'single_room' with arguments '(3,)' not found. 1 pattern(s) tried: ['$(?P<pk>[0-9]+)']
ERROR:django.request:Internal Server Error: /
Traceback (most recent call last):
  File "/usr/local/lib/python3.5/dist-packages/django/core/handlers/exception.py", line 35, in inner
    response = get_response(request)
  File "/usr/local/lib/python3.5/dist-packages/django/core/handlers/base.py", line 158, in _get_response
    response = self.process_exception_by_middleware(e, request)
  File "/usr/local/lib/python3.5/dist-packages/channels/handler.py", line 243, in process_exception_by_middleware
    return super(AsgiHandler, self).process_exception_by_middleware(exception, request)
  File "/usr/local/lib/python3.5/dist-packages/django/core/handlers/base.py", line 156, in _get_response
    response = response.render()
  File "/usr/local/lib/python3.5/dist-packages/django/template/response.py", line 106, in render
    self.content = self.rendered_content
  File "/usr/local/lib/python3.5/dist-packages/django/template/response.py", line 83, in rendered_content
    content = template.render(context, self._request)
  File "/usr/local/lib/python3.5/dist-packages/django/template/backends/django.py", line 61, in render
    return self.template.render(context)
  File "/usr/local/lib/python3.5/dist-packages/django/template/base.py", line 175, in render
    return self._render(context)
  File "/usr/local/lib/python3.5/dist-packages/django/template/base.py", line 167, in _render
    return self.nodelist.render(context)
  File "/usr/local/lib/python3.5/dist-packages/django/template/base.py", line 943, in render
    bit = node.render_annotated(context)
  File "/usr/local/lib/python3.5/dist-packages/django/template/base.py", line 910, in render_annotated
    return self.render(context)
  File "/usr/local/lib/python3.5/dist-packages/django/template/loader_tags.py", line 155, in render
    return compiled_parent._render(context)
  File "/usr/local/lib/python3.5/dist-packages/django/template/base.py", line 167, in _render
    return self.nodelist.render(context)
  File "/usr/local/lib/python3.5/dist-packages/django/template/base.py", line 943, in render
    bit = node.render_annotated(context)
  File "/usr/local/lib/python3.5/dist-packages/django/template/base.py", line 910, in render_annotated
    return self.render(context)
  File "/usr/local/lib/python3.5/dist-packages/django/template/loader_tags.py", line 67, in render
    result = block.nodelist.render(context)
  File "/usr/local/lib/python3.5/dist-packages/django/template/base.py", line 943, in render
    bit = node.render_annotated(context)
  File "/usr/local/lib/python3.5/dist-packages/django/template/base.py", line 910, in render_annotated
    return self.render(context)
  File "/usr/local/lib/python3.5/dist-packages/django/template/defaulttags.py", line 211, in render
    nodelist.append(node.render_annotated(context))
  File "/usr/local/lib/python3.5/dist-packages/django/template/base.py", line 910, in render_annotated
    return self.render(context)
  File "/usr/local/lib/python3.5/dist-packages/django/template/defaulttags.py", line 447, in render
    url = reverse(view_name, args=args, kwargs=kwargs, current_app=current_app)
  File "/usr/local/lib/python3.5/dist-packages/django/urls/base.py", line 88, in reverse
    return iri_to_uri(resolver._reverse_with_prefix(view, prefix, *args, **kwargs))
  File "/usr/local/lib/python3.5/dist-packages/django/urls/resolvers.py", line 632, in _reverse_with_prefix
    raise NoReverseMatch(msg)
django.urls.exceptions.NoReverseMatch: Reverse for 'single_room' with arguments '(3,)' not found. 1 pattern(s) tried: ['$(?P<pk>[0-9]+)']
ERROR:django.request:Internal Server Error: /
Traceback (most recent call last):
  File "/usr/local/lib/python3.5/dist-packages/django/core/handlers/exception.py", line 35, in inner
    response = get_response(request)
  File "/usr/local/lib/python3.5/dist-packages/django/core/handlers/base.py", line 158, in _get_response
    response = self.process_exception_by_middleware(e, request)
  File "/usr/local/lib/python3.5/dist-packages/channels/handler.py", line 243, in process_exception_by_middleware
    return super(AsgiHandler, self).process_exception_by_middleware(exception, request)
  File "/usr/local/lib/python3.5/dist-packages/django/core/handlers/base.py", line 156, in _get_response
    response = response.render()
  File "/usr/local/lib/python3.5/dist-packages/django/template/response.py", line 106, in render
    self.content = self.rendered_content
  File "/usr/local/lib/python3.5/dist-packages/django/template/response.py", line 83, in rendered_content
    content = template.render(context, self._request)
  File "/usr/local/lib/python3.5/dist-packages/django/template/backends/django.py", line 61, in render
    return self.template.render(context)
  File "/usr/local/lib/python3.5/dist-packages/django/template/base.py", line 175, in render
    return self._render(context)
  File "/usr/local/lib/python3.5/dist-packages/django/template/base.py", line 167, in _render
    return self.nodelist.render(context)
  File "/usr/local/lib/python3.5/dist-packages/django/template/base.py", line 943, in render
    bit = node.render_annotated(context)
  File "/usr/local/lib/python3.5/dist-packages/django/template/base.py", line 910, in render_annotated
    return self.render(context)
  File "/usr/local/lib/python3.5/dist-packages/django/template/loader_tags.py", line 155, in render
    return compiled_parent._render(context)
  File "/usr/local/lib/python3.5/dist-packages/django/template/base.py", line 167, in _render
    return self.nodelist.render(context)
  File "/usr/local/lib/python3.5/dist-packages/django/template/base.py", line 943, in render
    bit = node.render_annotated(context)
  File "/usr/local/lib/python3.5/dist-packages/django/template/base.py", line 910, in render_annotated
    return self.render(context)
  File "/usr/local/lib/python3.5/dist-packages/django/template/loader_tags.py", line 67, in render
    result = block.nodelist.render(context)
  File "/usr/local/lib/python3.5/dist-packages/django/template/base.py", line 943, in render
    bit = node.render_annotated(context)
  File "/usr/local/lib/python3.5/dist-packages/django/template/base.py", line 910, in render_annotated
    return self.render(context)
  File "/usr/local/lib/python3.5/dist-packages/django/template/defaulttags.py", line 211, in render
    nodelist.append(node.render_annotated(context))
  File "/usr/local/lib/python3.5/dist-packages/django/template/base.py", line 910, in render_annotated
    return self.render(context)
  File "/usr/local/lib/python3.5/dist-packages/django/template/defaulttags.py", line 447, in render
    url = reverse(view_name, args=args, kwargs=kwargs, current_app=current_app)
  File "/usr/local/lib/python3.5/dist-packages/django/urls/base.py", line 88, in reverse
    return iri_to_uri(resolver._reverse_with_prefix(view, prefix, *args, **kwargs))
  File "/usr/local/lib/python3.5/dist-packages/django/urls/resolvers.py", line 632, in _reverse_with_prefix
    raise NoReverseMatch(msg)
django.urls.exceptions.NoReverseMatch: Reverse for 'single_room' with arguments '(3,)' not found. 1 pattern(s) tried: ['$(?P<pk>[0-9]+)']
ERROR:django.request:Internal Server Error: /
Traceback (most recent call last):
  File "/usr/local/lib/python3.5/dist-packages/django/core/handlers/exception.py", line 35, in inner
    response = get_response(request)
  File "/usr/local/lib/python3.5/dist-packages/django/core/handlers/base.py", line 158, in _get_response
    response = self.process_exception_by_middleware(e, request)
  File "/usr/local/lib/python3.5/dist-packages/channels/handler.py", line 243, in process_exception_by_middleware
    return super(AsgiHandler, self).process_exception_by_middleware(exception, request)
  File "/usr/local/lib/python3.5/dist-packages/django/core/handlers/base.py", line 156, in _get_response
    response = response.render()
  File "/usr/local/lib/python3.5/dist-packages/django/template/response.py", line 106, in render
    self.content = self.rendered_content
  File "/usr/local/lib/python3.5/dist-packages/django/template/response.py", line 83, in rendered_content
    content = template.render(context, self._request)
  File "/usr/local/lib/python3.5/dist-packages/django/template/backends/django.py", line 61, in render
    return self.template.render(context)
  File "/usr/local/lib/python3.5/dist-packages/django/template/base.py", line 175, in render
    return self._render(context)
  File "/usr/local/lib/python3.5/dist-packages/django/template/base.py", line 167, in _render
    return self.nodelist.render(context)
  File "/usr/local/lib/python3.5/dist-packages/django/template/base.py", line 943, in render
    bit = node.render_annotated(context)
  File "/usr/local/lib/python3.5/dist-packages/django/template/base.py", line 910, in render_annotated
    return self.render(context)
  File "/usr/local/lib/python3.5/dist-packages/django/template/loader_tags.py", line 155, in render
    return compiled_parent._render(context)
  File "/usr/local/lib/python3.5/dist-packages/django/template/base.py", line 167, in _render
    return self.nodelist.render(context)
  File "/usr/local/lib/python3.5/dist-packages/django/template/base.py", line 943, in render
    bit = node.render_annotated(context)
  File "/usr/local/lib/python3.5/dist-packages/django/template/base.py", line 910, in render_annotated
    return self.render(context)
  File "/usr/local/lib/python3.5/dist-packages/django/template/loader_tags.py", line 67, in render
    result = block.nodelist.render(context)
  File "/usr/local/lib/python3.5/dist-packages/django/template/base.py", line 943, in render
    bit = node.render_annotated(context)
  File "/usr/local/lib/python3.5/dist-packages/django/template/base.py", line 910, in render_annotated
    return self.render(context)
  File "/usr/local/lib/python3.5/dist-packages/django/template/defaulttags.py", line 211, in render
    nodelist.append(node.render_annotated(context))
  File "/usr/local/lib/python3.5/dist-packages/django/template/base.py", line 910, in render_annotated
    return self.render(context)
  File "/usr/local/lib/python3.5/dist-packages/django/template/defaulttags.py", line 447, in render
    url = reverse(view_name, args=args, kwargs=kwargs, current_app=current_app)
  File "/usr/local/lib/python3.5/dist-packages/django/urls/base.py", line 88, in reverse
    return iri_to_uri(resolver._reverse_with_prefix(view, prefix, *args, **kwargs))
  File "/usr/local/lib/python3.5/dist-packages/django/urls/resolvers.py", line 632, in _reverse_with_prefix
    raise NoReverseMatch(msg)
django.urls.exceptions.NoReverseMatch: Reverse for 'single_room' with arguments '(3,)' not found. 1 pattern(s) tried: ['$(?P<pk>[0-9]+)']
ERROR:django.request:Internal Server Error: /
Traceback (most recent call last):
  File "/usr/local/lib/python3.5/dist-packages/django/core/handlers/exception.py", line 35, in inner
    response = get_response(request)
  File "/usr/local/lib/python3.5/dist-packages/django/core/handlers/base.py", line 158, in _get_response
    response = self.process_exception_by_middleware(e, request)
  File "/usr/local/lib/python3.5/dist-packages/channels/handler.py", line 243, in process_exception_by_middleware
    return super(AsgiHandler, self).process_exception_by_middleware(exception, request)
  File "/usr/local/lib/python3.5/dist-packages/django/core/handlers/base.py", line 156, in _get_response
    response = response.render()
  File "/usr/local/lib/python3.5/dist-packages/django/template/response.py", line 106, in render
    self.content = self.rendered_content
  File "/usr/local/lib/python3.5/dist-packages/django/template/response.py", line 83, in rendered_content
    content = template.render(context, self._request)
  File "/usr/local/lib/python3.5/dist-packages/django/template/backends/django.py", line 61, in render
    return self.template.render(context)
  File "/usr/local/lib/python3.5/dist-packages/django/template/base.py", line 175, in render
    return self._render(context)
  File "/usr/local/lib/python3.5/dist-packages/django/template/base.py", line 167, in _render
    return self.nodelist.render(context)
  File "/usr/local/lib/python3.5/dist-packages/django/template/base.py", line 943, in render
    bit = node.render_annotated(context)
  File "/usr/local/lib/python3.5/dist-packages/django/template/base.py", line 910, in render_annotated
    return self.render(context)
  File "/usr/local/lib/python3.5/dist-packages/django/template/loader_tags.py", line 155, in render
    return compiled_parent._render(context)
  File "/usr/local/lib/python3.5/dist-packages/django/template/base.py", line 167, in _render
    return self.nodelist.render(context)
  File "/usr/local/lib/python3.5/dist-packages/django/template/base.py", line 943, in render
    bit = node.render_annotated(context)
  File "/usr/local/lib/python3.5/dist-packages/django/template/base.py", line 910, in render_annotated
    return self.render(context)
  File "/usr/local/lib/python3.5/dist-packages/django/template/loader_tags.py", line 67, in render
    result = block.nodelist.render(context)
  File "/usr/local/lib/python3.5/dist-packages/django/template/base.py", line 943, in render
    bit = node.render_annotated(context)
  File "/usr/local/lib/python3.5/dist-packages/django/template/base.py", line 910, in render_annotated
    return self.render(context)
  File "/usr/local/lib/python3.5/dist-packages/django/template/defaulttags.py", line 211, in render
    nodelist.append(node.render_annotated(context))
  File "/usr/local/lib/python3.5/dist-packages/django/template/base.py", line 910, in render_annotated
    return self.render(context)
  File "/usr/local/lib/python3.5/dist-packages/django/template/defaulttags.py", line 447, in render
    url = reverse(view_name, args=args, kwargs=kwargs, current_app=current_app)
  File "/usr/local/lib/python3.5/dist-packages/django/urls/base.py", line 88, in reverse
    return iri_to_uri(resolver._reverse_with_prefix(view, prefix, *args, **kwargs))
  File "/usr/local/lib/python3.5/dist-packages/django/urls/resolvers.py", line 632, in _reverse_with_prefix
    raise NoReverseMatch(msg)
django.urls.exceptions.NoReverseMatch: Reverse for 'single_room' with arguments '(3,)' not found. 1 pattern(s) tried: ['$(?P<pk>[0-9]+)']
INFO:daphne.server:HTTP/2 support not enabled (install the http2 and tls Twisted extras)
INFO:daphne.server:Using busy-loop synchronous mode on channel layer
INFO:daphne.server:Listening on endpoint tcp:port=8000:interface=127.0.0.1
ERROR:django.request:Internal Server Error: /
Traceback (most recent call last):
  File "/usr/local/lib/python3.5/dist-packages/django/core/handlers/exception.py", line 35, in inner
    response = get_response(request)
  File "/usr/local/lib/python3.5/dist-packages/django/core/handlers/base.py", line 158, in _get_response
    response = self.process_exception_by_middleware(e, request)
  File "/usr/local/lib/python3.5/dist-packages/channels/handler.py", line 243, in process_exception_by_middleware
    return super(AsgiHandler, self).process_exception_by_middleware(exception, request)
  File "/usr/local/lib/python3.5/dist-packages/django/core/handlers/base.py", line 156, in _get_response
    response = response.render()
  File "/usr/local/lib/python3.5/dist-packages/django/template/response.py", line 106, in render
    self.content = self.rendered_content
  File "/usr/local/lib/python3.5/dist-packages/django/template/response.py", line 83, in rendered_content
    content = template.render(context, self._request)
  File "/usr/local/lib/python3.5/dist-packages/django/template/backends/django.py", line 61, in render
    return self.template.render(context)
  File "/usr/local/lib/python3.5/dist-packages/django/template/base.py", line 175, in render
    return self._render(context)
  File "/usr/local/lib/python3.5/dist-packages/django/template/base.py", line 167, in _render
    return self.nodelist.render(context)
  File "/usr/local/lib/python3.5/dist-packages/django/template/base.py", line 943, in render
    bit = node.render_annotated(context)
  File "/usr/local/lib/python3.5/dist-packages/django/template/base.py", line 910, in render_annotated
    return self.render(context)
  File "/usr/local/lib/python3.5/dist-packages/django/template/loader_tags.py", line 155, in render
    return compiled_parent._render(context)
  File "/usr/local/lib/python3.5/dist-packages/django/template/base.py", line 167, in _render
    return self.nodelist.render(context)
  File "/usr/local/lib/python3.5/dist-packages/django/template/base.py", line 943, in render
    bit = node.render_annotated(context)
  File "/usr/local/lib/python3.5/dist-packages/django/template/base.py", line 910, in render_annotated
    return self.render(context)
  File "/usr/local/lib/python3.5/dist-packages/django/template/loader_tags.py", line 67, in render
    result = block.nodelist.render(context)
  File "/usr/local/lib/python3.5/dist-packages/django/template/base.py", line 943, in render
    bit = node.render_annotated(context)
  File "/usr/local/lib/python3.5/dist-packages/django/template/base.py", line 910, in render_annotated
    return self.render(context)
  File "/usr/local/lib/python3.5/dist-packages/django/template/defaulttags.py", line 211, in render
    nodelist.append(node.render_annotated(context))
  File "/usr/local/lib/python3.5/dist-packages/django/template/base.py", line 910, in render_annotated
    return self.render(context)
  File "/usr/local/lib/python3.5/dist-packages/django/template/defaulttags.py", line 447, in render
    url = reverse(view_name, args=args, kwargs=kwargs, current_app=current_app)
  File "/usr/local/lib/python3.5/dist-packages/django/urls/base.py", line 88, in reverse
    return iri_to_uri(resolver._reverse_with_prefix(view, prefix, *args, **kwargs))
  File "/usr/local/lib/python3.5/dist-packages/django/urls/resolvers.py", line 632, in _reverse_with_prefix
    raise NoReverseMatch(msg)
django.urls.exceptions.NoReverseMatch: Reverse for 'single_room' with arguments '(3,)' not found. 1 pattern(s) tried: ['$room/(?P<pk>[0-9]+)']
ERROR:django.request:Internal Server Error: /
Traceback (most recent call last):
  File "/usr/local/lib/python3.5/dist-packages/django/core/handlers/exception.py", line 35, in inner
    response = get_response(request)
  File "/usr/local/lib/python3.5/dist-packages/django/core/handlers/base.py", line 158, in _get_response
    response = self.process_exception_by_middleware(e, request)
  File "/usr/local/lib/python3.5/dist-packages/channels/handler.py", line 243, in process_exception_by_middleware
    return super(AsgiHandler, self).process_exception_by_middleware(exception, request)
  File "/usr/local/lib/python3.5/dist-packages/django/core/handlers/base.py", line 156, in _get_response
    response = response.render()
  File "/usr/local/lib/python3.5/dist-packages/django/template/response.py", line 106, in render
    self.content = self.rendered_content
  File "/usr/local/lib/python3.5/dist-packages/django/template/response.py", line 83, in rendered_content
    content = template.render(context, self._request)
  File "/usr/local/lib/python3.5/dist-packages/django/template/backends/django.py", line 61, in render
    return self.template.render(context)
  File "/usr/local/lib/python3.5/dist-packages/django/template/base.py", line 175, in render
    return self._render(context)
  File "/usr/local/lib/python3.5/dist-packages/django/template/base.py", line 167, in _render
    return self.nodelist.render(context)
  File "/usr/local/lib/python3.5/dist-packages/django/template/base.py", line 943, in render
    bit = node.render_annotated(context)
  File "/usr/local/lib/python3.5/dist-packages/django/template/base.py", line 910, in render_annotated
    return self.render(context)
  File "/usr/local/lib/python3.5/dist-packages/django/template/loader_tags.py", line 155, in render
    return compiled_parent._render(context)
  File "/usr/local/lib/python3.5/dist-packages/django/template/base.py", line 167, in _render
    return self.nodelist.render(context)
  File "/usr/local/lib/python3.5/dist-packages/django/template/base.py", line 943, in render
    bit = node.render_annotated(context)
  File "/usr/local/lib/python3.5/dist-packages/django/template/base.py", line 910, in render_annotated
    return self.render(context)
  File "/usr/local/lib/python3.5/dist-packages/django/template/loader_tags.py", line 67, in render
    result = block.nodelist.render(context)
  File "/usr/local/lib/python3.5/dist-packages/django/template/base.py", line 943, in render
    bit = node.render_annotated(context)
  File "/usr/local/lib/python3.5/dist-packages/django/template/base.py", line 910, in render_annotated
    return self.render(context)
  File "/usr/local/lib/python3.5/dist-packages/django/template/defaulttags.py", line 211, in render
    nodelist.append(node.render_annotated(context))
  File "/usr/local/lib/python3.5/dist-packages/django/template/base.py", line 910, in render_annotated
    return self.render(context)
  File "/usr/local/lib/python3.5/dist-packages/django/template/defaulttags.py", line 447, in render
    url = reverse(view_name, args=args, kwargs=kwargs, current_app=current_app)
  File "/usr/local/lib/python3.5/dist-packages/django/urls/base.py", line 88, in reverse
    return iri_to_uri(resolver._reverse_with_prefix(view, prefix, *args, **kwargs))
  File "/usr/local/lib/python3.5/dist-packages/django/urls/resolvers.py", line 632, in _reverse_with_prefix
    raise NoReverseMatch(msg)
django.urls.exceptions.NoReverseMatch: Reverse for 'single_room' with arguments '(3,)' not found. 1 pattern(s) tried: ['$room/(?P<pk>[0-9]+)']
INFO:daphne.server:HTTP/2 support not enabled (install the http2 and tls Twisted extras)
INFO:daphne.server:Using busy-loop synchronous mode on channel layer
INFO:daphne.server:Listening on endpoint tcp:port=8000:interface=127.0.0.1
ERROR:django.request:Internal Server Error: /
Traceback (most recent call last):
  File "/usr/local/lib/python3.5/dist-packages/django/core/handlers/exception.py", line 35, in inner
    response = get_response(request)
  File "/usr/local/lib/python3.5/dist-packages/django/core/handlers/base.py", line 158, in _get_response
    response = self.process_exception_by_middleware(e, request)
  File "/usr/local/lib/python3.5/dist-packages/channels/handler.py", line 243, in process_exception_by_middleware
    return super(AsgiHandler, self).process_exception_by_middleware(exception, request)
  File "/usr/local/lib/python3.5/dist-packages/django/core/handlers/base.py", line 156, in _get_response
    response = response.render()
  File "/usr/local/lib/python3.5/dist-packages/django/template/response.py", line 106, in render
    self.content = self.rendered_content
  File "/usr/local/lib/python3.5/dist-packages/django/template/response.py", line 83, in rendered_content
    content = template.render(context, self._request)
  File "/usr/local/lib/python3.5/dist-packages/django/template/backends/django.py", line 61, in render
    return self.template.render(context)
  File "/usr/local/lib/python3.5/dist-packages/django/template/base.py", line 175, in render
    return self._render(context)
  File "/usr/local/lib/python3.5/dist-packages/django/template/base.py", line 167, in _render
    return self.nodelist.render(context)
  File "/usr/local/lib/python3.5/dist-packages/django/template/base.py", line 943, in render
    bit = node.render_annotated(context)
  File "/usr/local/lib/python3.5/dist-packages/django/template/base.py", line 910, in render_annotated
    return self.render(context)
  File "/usr/local/lib/python3.5/dist-packages/django/template/loader_tags.py", line 155, in render
    return compiled_parent._render(context)
  File "/usr/local/lib/python3.5/dist-packages/django/template/base.py", line 167, in _render
    return self.nodelist.render(context)
  File "/usr/local/lib/python3.5/dist-packages/django/template/base.py", line 943, in render
    bit = node.render_annotated(context)
  File "/usr/local/lib/python3.5/dist-packages/django/template/base.py", line 910, in render_annotated
    return self.render(context)
  File "/usr/local/lib/python3.5/dist-packages/django/template/loader_tags.py", line 67, in render
    result = block.nodelist.render(context)
  File "/usr/local/lib/python3.5/dist-packages/django/template/base.py", line 943, in render
    bit = node.render_annotated(context)
  File "/usr/local/lib/python3.5/dist-packages/django/template/base.py", line 910, in render_annotated
    return self.render(context)
  File "/usr/local/lib/python3.5/dist-packages/django/template/defaulttags.py", line 211, in render
    nodelist.append(node.render_annotated(context))
  File "/usr/local/lib/python3.5/dist-packages/django/template/base.py", line 910, in render_annotated
    return self.render(context)
  File "/usr/local/lib/python3.5/dist-packages/django/template/defaulttags.py", line 447, in render
    url = reverse(view_name, args=args, kwargs=kwargs, current_app=current_app)
  File "/usr/local/lib/python3.5/dist-packages/django/urls/base.py", line 88, in reverse
    return iri_to_uri(resolver._reverse_with_prefix(view, prefix, *args, **kwargs))
  File "/usr/local/lib/python3.5/dist-packages/django/urls/resolvers.py", line 632, in _reverse_with_prefix
    raise NoReverseMatch(msg)
django.urls.exceptions.NoReverseMatch: Reverse for 'single_room' with arguments '(3,)' not found. 1 pattern(s) tried: ['$room/(?P<pk>[0-9]+)$']
ERROR:django.request:Internal Server Error: /
Traceback (most recent call last):
  File "/usr/local/lib/python3.5/dist-packages/django/core/handlers/exception.py", line 35, in inner
    response = get_response(request)
  File "/usr/local/lib/python3.5/dist-packages/django/core/handlers/base.py", line 158, in _get_response
    response = self.process_exception_by_middleware(e, request)
  File "/usr/local/lib/python3.5/dist-packages/channels/handler.py", line 243, in process_exception_by_middleware
    return super(AsgiHandler, self).process_exception_by_middleware(exception, request)
  File "/usr/local/lib/python3.5/dist-packages/django/core/handlers/base.py", line 156, in _get_response
    response = response.render()
  File "/usr/local/lib/python3.5/dist-packages/django/template/response.py", line 106, in render
    self.content = self.rendered_content
  File "/usr/local/lib/python3.5/dist-packages/django/template/response.py", line 83, in rendered_content
    content = template.render(context, self._request)
  File "/usr/local/lib/python3.5/dist-packages/django/template/backends/django.py", line 61, in render
    return self.template.render(context)
  File "/usr/local/lib/python3.5/dist-packages/django/template/base.py", line 175, in render
    return self._render(context)
  File "/usr/local/lib/python3.5/dist-packages/django/template/base.py", line 167, in _render
    return self.nodelist.render(context)
  File "/usr/local/lib/python3.5/dist-packages/django/template/base.py", line 943, in render
    bit = node.render_annotated(context)
  File "/usr/local/lib/python3.5/dist-packages/django/template/base.py", line 910, in render_annotated
    return self.render(context)
  File "/usr/local/lib/python3.5/dist-packages/django/template/loader_tags.py", line 155, in render
    return compiled_parent._render(context)
  File "/usr/local/lib/python3.5/dist-packages/django/template/base.py", line 167, in _render
    return self.nodelist.render(context)
  File "/usr/local/lib/python3.5/dist-packages/django/template/base.py", line 943, in render
    bit = node.render_annotated(context)
  File "/usr/local/lib/python3.5/dist-packages/django/template/base.py", line 910, in render_annotated
    return self.render(context)
  File "/usr/local/lib/python3.5/dist-packages/django/template/loader_tags.py", line 67, in render
    result = block.nodelist.render(context)
  File "/usr/local/lib/python3.5/dist-packages/django/template/base.py", line 943, in render
    bit = node.render_annotated(context)
  File "/usr/local/lib/python3.5/dist-packages/django/template/base.py", line 910, in render_annotated
    return self.render(context)
  File "/usr/local/lib/python3.5/dist-packages/django/template/defaulttags.py", line 211, in render
    nodelist.append(node.render_annotated(context))
  File "/usr/local/lib/python3.5/dist-packages/django/template/base.py", line 910, in render_annotated
    return self.render(context)
  File "/usr/local/lib/python3.5/dist-packages/django/template/defaulttags.py", line 447, in render
    url = reverse(view_name, args=args, kwargs=kwargs, current_app=current_app)
  File "/usr/local/lib/python3.5/dist-packages/django/urls/base.py", line 88, in reverse
    return iri_to_uri(resolver._reverse_with_prefix(view, prefix, *args, **kwargs))
  File "/usr/local/lib/python3.5/dist-packages/django/urls/resolvers.py", line 632, in _reverse_with_prefix
    raise NoReverseMatch(msg)
django.urls.exceptions.NoReverseMatch: Reverse for 'single_room' with arguments '(3,)' not found. 1 pattern(s) tried: ['$room/(?P<pk>[0-9]+)$']
ERROR:django.request:Internal Server Error: /
Traceback (most recent call last):
  File "/usr/local/lib/python3.5/dist-packages/django/core/handlers/exception.py", line 35, in inner
    response = get_response(request)
  File "/usr/local/lib/python3.5/dist-packages/django/core/handlers/base.py", line 158, in _get_response
    response = self.process_exception_by_middleware(e, request)
  File "/usr/local/lib/python3.5/dist-packages/channels/handler.py", line 243, in process_exception_by_middleware
    return super(AsgiHandler, self).process_exception_by_middleware(exception, request)
  File "/usr/local/lib/python3.5/dist-packages/django/core/handlers/base.py", line 156, in _get_response
    response = response.render()
  File "/usr/local/lib/python3.5/dist-packages/django/template/response.py", line 106, in render
    self.content = self.rendered_content
  File "/usr/local/lib/python3.5/dist-packages/django/template/response.py", line 83, in rendered_content
    content = template.render(context, self._request)
  File "/usr/local/lib/python3.5/dist-packages/django/template/backends/django.py", line 61, in render
    return self.template.render(context)
  File "/usr/local/lib/python3.5/dist-packages/django/template/base.py", line 175, in render
    return self._render(context)
  File "/usr/local/lib/python3.5/dist-packages/django/template/base.py", line 167, in _render
    return self.nodelist.render(context)
  File "/usr/local/lib/python3.5/dist-packages/django/template/base.py", line 943, in render
    bit = node.render_annotated(context)
  File "/usr/local/lib/python3.5/dist-packages/django/template/base.py", line 910, in render_annotated
    return self.render(context)
  File "/usr/local/lib/python3.5/dist-packages/django/template/loader_tags.py", line 155, in render
    return compiled_parent._render(context)
  File "/usr/local/lib/python3.5/dist-packages/django/template/base.py", line 167, in _render
    return self.nodelist.render(context)
  File "/usr/local/lib/python3.5/dist-packages/django/template/base.py", line 943, in render
    bit = node.render_annotated(context)
  File "/usr/local/lib/python3.5/dist-packages/django/template/base.py", line 910, in render_annotated
    return self.render(context)
  File "/usr/local/lib/python3.5/dist-packages/django/template/loader_tags.py", line 67, in render
    result = block.nodelist.render(context)
  File "/usr/local/lib/python3.5/dist-packages/django/template/base.py", line 943, in render
    bit = node.render_annotated(context)
  File "/usr/local/lib/python3.5/dist-packages/django/template/base.py", line 910, in render_annotated
    return self.render(context)
  File "/usr/local/lib/python3.5/dist-packages/django/template/defaulttags.py", line 211, in render
    nodelist.append(node.render_annotated(context))
  File "/usr/local/lib/python3.5/dist-packages/django/template/base.py", line 910, in render_annotated
    return self.render(context)
  File "/usr/local/lib/python3.5/dist-packages/django/template/defaulttags.py", line 447, in render
    url = reverse(view_name, args=args, kwargs=kwargs, current_app=current_app)
  File "/usr/local/lib/python3.5/dist-packages/django/urls/base.py", line 88, in reverse
    return iri_to_uri(resolver._reverse_with_prefix(view, prefix, *args, **kwargs))
  File "/usr/local/lib/python3.5/dist-packages/django/urls/resolvers.py", line 632, in _reverse_with_prefix
    raise NoReverseMatch(msg)
django.urls.exceptions.NoReverseMatch: Reverse for 'single_room' with arguments '(3,)' not found. 1 pattern(s) tried: ['$room/(?P<pk>[0-9]+)$']
WARNING:django.request:Not Found: /room/1
WARNING:django.request:Not Found: /room/1
INFO:daphne.server:HTTP/2 support not enabled (install the http2 and tls Twisted extras)
INFO:daphne.server:Using busy-loop synchronous mode on channel layer
INFO:daphne.server:Listening on endpoint tcp:port=8000:interface=127.0.0.1
WARNING:django.request:Not Found: /room/1
WARNING:django.request:Not Found: /room/1
WARNING:django.request:Not Found: /room/1
WARNING:django.request:Not Found: /room/1
WARNING:django.request:Not Found: /room/1
INFO:daphne.server:HTTP/2 support not enabled (install the http2 and tls Twisted extras)
INFO:daphne.server:Using busy-loop synchronous mode on channel layer
INFO:daphne.server:Listening on endpoint tcp:port=8000:interface=127.0.0.1
ERROR:django.request:Internal Server Error: /room/1
Traceback (most recent call last):
  File "/usr/local/lib/python3.5/dist-packages/django/core/handlers/exception.py", line 35, in inner
    response = get_response(request)
  File "/usr/local/lib/python3.5/dist-packages/django/core/handlers/base.py", line 128, in _get_response
    response = self.process_exception_by_middleware(e, request)
  File "/usr/local/lib/python3.5/dist-packages/channels/handler.py", line 243, in process_exception_by_middleware
    return super(AsgiHandler, self).process_exception_by_middleware(exception, request)
  File "/usr/local/lib/python3.5/dist-packages/django/core/handlers/base.py", line 126, in _get_response
    response = wrapped_callback(request, *callback_args, **callback_kwargs)
TypeError: __init__() takes 1 positional argument but 2 were given
ERROR:django.request:Internal Server Error: /room/1
Traceback (most recent call last):
  File "/usr/local/lib/python3.5/dist-packages/django/core/handlers/exception.py", line 35, in inner
    response = get_response(request)
  File "/usr/local/lib/python3.5/dist-packages/django/core/handlers/base.py", line 128, in _get_response
    response = self.process_exception_by_middleware(e, request)
  File "/usr/local/lib/python3.5/dist-packages/channels/handler.py", line 243, in process_exception_by_middleware
    return super(AsgiHandler, self).process_exception_by_middleware(exception, request)
  File "/usr/local/lib/python3.5/dist-packages/django/core/handlers/base.py", line 126, in _get_response
    response = wrapped_callback(request, *callback_args, **callback_kwargs)
TypeError: __init__() takes 1 positional argument but 2 were given
WARNING:django.request:Not Found: /1
ERROR:django.request:Internal Server Error: /room/1
Traceback (most recent call last):
  File "/usr/local/lib/python3.5/dist-packages/django/core/handlers/exception.py", line 35, in inner
    response = get_response(request)
  File "/usr/local/lib/python3.5/dist-packages/django/core/handlers/base.py", line 128, in _get_response
    response = self.process_exception_by_middleware(e, request)
  File "/usr/local/lib/python3.5/dist-packages/channels/handler.py", line 243, in process_exception_by_middleware
    return super(AsgiHandler, self).process_exception_by_middleware(exception, request)
  File "/usr/local/lib/python3.5/dist-packages/django/core/handlers/base.py", line 126, in _get_response
    response = wrapped_callback(request, *callback_args, **callback_kwargs)
TypeError: __init__() takes 1 positional argument but 2 were given
ERROR:django.request:Internal Server Error: /room/1
Traceback (most recent call last):
  File "/usr/local/lib/python3.5/dist-packages/django/core/handlers/exception.py", line 35, in inner
    response = get_response(request)
  File "/usr/local/lib/python3.5/dist-packages/django/core/handlers/base.py", line 128, in _get_response
    response = self.process_exception_by_middleware(e, request)
  File "/usr/local/lib/python3.5/dist-packages/channels/handler.py", line 243, in process_exception_by_middleware
    return super(AsgiHandler, self).process_exception_by_middleware(exception, request)
  File "/usr/local/lib/python3.5/dist-packages/django/core/handlers/base.py", line 126, in _get_response
    response = wrapped_callback(request, *callback_args, **callback_kwargs)
TypeError: __init__() takes 1 positional argument but 2 were given
ERROR:django.request:Internal Server Error: /room/1
Traceback (most recent call last):
  File "/usr/local/lib/python3.5/dist-packages/django/core/handlers/exception.py", line 35, in inner
    response = get_response(request)
  File "/usr/local/lib/python3.5/dist-packages/django/core/handlers/base.py", line 128, in _get_response
    response = self.process_exception_by_middleware(e, request)
  File "/usr/local/lib/python3.5/dist-packages/channels/handler.py", line 243, in process_exception_by_middleware
    return super(AsgiHandler, self).process_exception_by_middleware(exception, request)
  File "/usr/local/lib/python3.5/dist-packages/django/core/handlers/base.py", line 126, in _get_response
    response = wrapped_callback(request, *callback_args, **callback_kwargs)
TypeError: __init__() takes 1 positional argument but 2 were given
ERROR:django.request:Internal Server Error: /room/1
Traceback (most recent call last):
  File "/usr/local/lib/python3.5/dist-packages/django/core/handlers/exception.py", line 35, in inner
    response = get_response(request)
  File "/usr/local/lib/python3.5/dist-packages/django/core/handlers/base.py", line 128, in _get_response
    response = self.process_exception_by_middleware(e, request)
  File "/usr/local/lib/python3.5/dist-packages/channels/handler.py", line 243, in process_exception_by_middleware
    return super(AsgiHandler, self).process_exception_by_middleware(exception, request)
  File "/usr/local/lib/python3.5/dist-packages/django/core/handlers/base.py", line 126, in _get_response
    response = wrapped_callback(request, *callback_args, **callback_kwargs)
TypeError: __init__() takes 1 positional argument but 2 were given
ERROR:django.request:Internal Server Error: /room/1
Traceback (most recent call last):
  File "/usr/local/lib/python3.5/dist-packages/django/core/handlers/exception.py", line 35, in inner
    response = get_response(request)
  File "/usr/local/lib/python3.5/dist-packages/django/core/handlers/base.py", line 128, in _get_response
    response = self.process_exception_by_middleware(e, request)
  File "/usr/local/lib/python3.5/dist-packages/channels/handler.py", line 243, in process_exception_by_middleware
    return super(AsgiHandler, self).process_exception_by_middleware(exception, request)
  File "/usr/local/lib/python3.5/dist-packages/django/core/handlers/base.py", line 126, in _get_response
    response = wrapped_callback(request, *callback_args, **callback_kwargs)
TypeError: __init__() takes 1 positional argument but 2 were given
ERROR:django.request:Internal Server Error: /room/1
Traceback (most recent call last):
  File "/usr/local/lib/python3.5/dist-packages/django/core/handlers/exception.py", line 35, in inner
    response = get_response(request)
  File "/usr/local/lib/python3.5/dist-packages/django/core/handlers/base.py", line 128, in _get_response
    response = self.process_exception_by_middleware(e, request)
  File "/usr/local/lib/python3.5/dist-packages/channels/handler.py", line 243, in process_exception_by_middleware
    return super(AsgiHandler, self).process_exception_by_middleware(exception, request)
  File "/usr/local/lib/python3.5/dist-packages/django/core/handlers/base.py", line 126, in _get_response
    response = wrapped_callback(request, *callback_args, **callback_kwargs)
TypeError: __init__() takes 1 positional argument but 2 were given
ERROR:django.request:Internal Server Error: /room/1
Traceback (most recent call last):
  File "/usr/local/lib/python3.5/dist-packages/django/core/handlers/exception.py", line 35, in inner
    response = get_response(request)
  File "/usr/local/lib/python3.5/dist-packages/django/core/handlers/base.py", line 128, in _get_response
    response = self.process_exception_by_middleware(e, request)
  File "/usr/local/lib/python3.5/dist-packages/channels/handler.py", line 243, in process_exception_by_middleware
    return super(AsgiHandler, self).process_exception_by_middleware(exception, request)
  File "/usr/local/lib/python3.5/dist-packages/django/core/handlers/base.py", line 126, in _get_response
    response = wrapped_callback(request, *callback_args, **callback_kwargs)
TypeError: __init__() takes 1 positional argument but 2 were given
INFO:daphne.server:HTTP/2 support not enabled (install the http2 and tls Twisted extras)
INFO:daphne.server:Using busy-loop synchronous mode on channel layer
INFO:daphne.server:Listening on endpoint tcp:port=8000:interface=127.0.0.1
INFO:daphne.server:HTTP/2 support not enabled (install the http2 and tls Twisted extras)
INFO:daphne.server:Using busy-loop synchronous mode on channel layer
INFO:daphne.server:Listening on endpoint tcp:port=8000:interface=127.0.0.1
INFO:daphne.server:HTTP/2 support not enabled (install the http2 and tls Twisted extras)
INFO:daphne.server:Using busy-loop synchronous mode on channel layer
INFO:daphne.server:Listening on endpoint tcp:port=8000:interface=127.0.0.1
INFO:root:the user dan has connected
INFO:root:the user dan has connected
INFO:daphne.server:HTTP/2 support not enabled (install the http2 and tls Twisted extras)
INFO:daphne.server:Using busy-loop synchronous mode on channel layer
INFO:daphne.server:Listening on endpoint tcp:port=8000:interface=127.0.0.1
INFO:root:the user dan has connected
INFO:daphne.server:HTTP/2 support not enabled (install the http2 and tls Twisted extras)
INFO:daphne.server:Using busy-loop synchronous mode on channel layer
INFO:daphne.server:Listening on endpoint tcp:port=8000:interface=127.0.0.1
WARNING:django.request:Not Found: /favicon.ico
INFO:root:the user dan has connected
INFO:root:the user dan has connected
INFO:root:the user amit has connected
INFO:daphne.server:HTTP/2 support not enabled (install the http2 and tls Twisted extras)
INFO:daphne.server:Using busy-loop synchronous mode on channel layer
INFO:daphne.server:Listening on endpoint tcp:port=8000:interface=127.0.0.1
INFO:root:the user amit has connected
INFO:root:the user amit has connected
INFO:daphne.server:HTTP/2 support not enabled (install the http2 and tls Twisted extras)
INFO:daphne.server:Using busy-loop synchronous mode on channel layer
INFO:daphne.server:Listening on endpoint tcp:port=8000:interface=127.0.0.1
INFO:root:the user amit has connected
INFO:root:the user dan has connected
INFO:daphne.server:HTTP/2 support not enabled (install the http2 and tls Twisted extras)
INFO:daphne.server:Using busy-loop synchronous mode on channel layer
INFO:daphne.server:Listening on endpoint tcp:port=8000:interface=127.0.0.1
INFO:daphne.server:HTTP/2 support not enabled (install the http2 and tls Twisted extras)
INFO:daphne.server:Using busy-loop synchronous mode on channel layer
INFO:daphne.server:Listening on endpoint tcp:port=8000:interface=127.0.0.1
INFO:daphne.server:HTTP/2 support not enabled (install the http2 and tls Twisted extras)
INFO:daphne.server:Using busy-loop synchronous mode on channel layer
INFO:daphne.server:Listening on endpoint tcp:port=8000:interface=127.0.0.1
INFO:root:the user dan has connected
INFO:daphne.server:HTTP/2 support not enabled (install the http2 and tls Twisted extras)
INFO:daphne.server:Using busy-loop synchronous mode on channel layer
INFO:daphne.server:Listening on endpoint tcp:port=8000:interface=127.0.0.1
INFO:root:the user dan has connected
INFO:daphne.server:HTTP/2 support not enabled (install the http2 and tls Twisted extras)
INFO:daphne.server:Using busy-loop synchronous mode on channel layer
INFO:daphne.server:Listening on endpoint tcp:port=8000:interface=127.0.0.1
INFO:daphne.server:HTTP/2 support not enabled (install the http2 and tls Twisted extras)
INFO:daphne.server:Using busy-loop synchronous mode on channel layer
INFO:daphne.server:Listening on endpoint tcp:port=8000:interface=127.0.0.1
INFO:root:the user dan has connected
INFO:root:the user dan has connected
INFO:daphne.server:HTTP/2 support not enabled (install the http2 and tls Twisted extras)
INFO:daphne.server:Using busy-loop synchronous mode on channel layer
INFO:daphne.server:Listening on endpoint tcp:port=8000:interface=127.0.0.1
INFO:root:the user dan has connected
INFO:daphne.server:HTTP/2 support not enabled (install the http2 and tls Twisted extras)
INFO:daphne.server:Using busy-loop synchronous mode on channel layer
INFO:daphne.server:Listening on endpoint tcp:port=8000:interface=127.0.0.1
INFO:root:the user dan has connected
INFO:daphne.server:HTTP/2 support not enabled (install the http2 and tls Twisted extras)
INFO:daphne.server:Using busy-loop synchronous mode on channel layer
INFO:daphne.server:Listening on endpoint tcp:port=8000:interface=127.0.0.1
INFO:root:the user dan has connected
INFO:daphne.server:HTTP/2 support not enabled (install the http2 and tls Twisted extras)
INFO:daphne.server:Using busy-loop synchronous mode on channel layer
INFO:daphne.server:Listening on endpoint tcp:port=8000:interface=127.0.0.1
INFO:root:the user dan has connected
INFO:daphne.server:HTTP/2 support not enabled (install the http2 and tls Twisted extras)
INFO:daphne.server:Using busy-loop synchronous mode on channel layer
INFO:daphne.server:Listening on endpoint tcp:port=8000:interface=127.0.0.1
INFO:root:the user dan has connected
INFO:root:the user dan has connected
INFO:daphne.server:HTTP/2 support not enabled (install the http2 and tls Twisted extras)
INFO:daphne.server:Using busy-loop synchronous mode on channel layer
INFO:daphne.server:Listening on endpoint tcp:port=8000:interface=127.0.0.1
INFO:root:the user dan has connected
WARNING:django.request:Not Found: //
WARNING:django.request:Not Found: /favicon.ico
INFO:root:the user amit has connected
INFO:root:the user dan has connected
INFO:daphne.server:HTTP/2 support not enabled (install the http2 and tls Twisted extras)
INFO:daphne.server:Using busy-loop synchronous mode on channel layer
INFO:daphne.server:Listening on endpoint tcp:port=8000:interface=127.0.0.1
INFO:daphne.server:HTTP/2 support not enabled (install the http2 and tls Twisted extras)
INFO:daphne.server:Using busy-loop synchronous mode on channel layer
INFO:daphne.server:Listening on endpoint tcp:port=8000:interface=127.0.0.1
INFO:root:the user dan has connected
INFO:root:the user amit has connected
INFO:root:the user dan has connected
INFO:root:the user amit has connected
INFO:root:the user dan has connected
INFO:root:the user amit has connected
INFO:root:the user dan has connected
INFO:root:the user amit has connected
INFO:root:the user dan has connected
INFO:root:the user amit has connected
INFO:daphne.server:HTTP/2 support not enabled (install the http2 and tls Twisted extras)
INFO:daphne.server:Using busy-loop synchronous mode on channel layer
INFO:daphne.server:Listening on endpoint tcp:port=8000:interface=127.0.0.1
ERROR:daphne.server:Error trying to receive messages: Error while reading from socket: (104, 'Connection reset by peer')
INFO:daphne.server:HTTP/2 support not enabled (install the http2 and tls Twisted extras)
INFO:daphne.server:Using busy-loop synchronous mode on channel layer
INFO:daphne.server:Listening on endpoint tcp:port=8000:interface=127.0.0.1
WARNING:django.request:Not Found: /favicon.ico
INFO:daphne.server:HTTP/2 support not enabled (install the http2 and tls Twisted extras)
INFO:daphne.server:Using busy-loop synchronous mode on channel layer
INFO:daphne.server:Listening on endpoint tcp:port=8000:interface=127.0.0.1
INFO:daphne.server:HTTP/2 support not enabled (install the http2 and tls Twisted extras)
INFO:daphne.server:Using busy-loop synchronous mode on channel layer
INFO:daphne.server:Listening on endpoint tcp:port=8000:interface=127.0.0.1
INFO:daphne.server:HTTP/2 support not enabled (install the http2 and tls Twisted extras)
INFO:daphne.server:Using busy-loop synchronous mode on channel layer
INFO:daphne.server:Listening on endpoint tcp:port=8000:interface=127.0.0.1
INFO:daphne.server:HTTP/2 support not enabled (install the http2 and tls Twisted extras)
INFO:daphne.server:Using busy-loop synchronous mode on channel layer
INFO:daphne.server:Listening on endpoint tcp:port=8000:interface=127.0.0.1
INFO:daphne.server:HTTP/2 support not enabled (install the http2 and tls Twisted extras)
INFO:daphne.server:Using busy-loop synchronous mode on channel layer
INFO:daphne.server:Listening on endpoint tcp:port=8000:interface=127.0.0.1
INFO:daphne.server:HTTP/2 support not enabled (install the http2 and tls Twisted extras)
INFO:daphne.server:Using busy-loop synchronous mode on channel layer
INFO:daphne.server:Listening on endpoint tcp:port=8000:interface=127.0.0.1
INFO:daphne.server:HTTP/2 support not enabled (install the http2 and tls Twisted extras)
INFO:daphne.server:Using busy-loop synchronous mode on channel layer
INFO:daphne.server:Listening on endpoint tcp:port=8000:interface=127.0.0.1
WARNING:django.request:Not Found: /accounts/static/doodles.png
WARNING:django.request:Not Found: /accounts/static/doodles.png
INFO:daphne.server:HTTP/2 support not enabled (install the http2 and tls Twisted extras)
INFO:daphne.server:Using busy-loop synchronous mode on channel layer
INFO:daphne.server:Listening on endpoint tcp:port=8000:interface=127.0.0.1
INFO:daphne.server:HTTP/2 support not enabled (install the http2 and tls Twisted extras)
INFO:daphne.server:Using busy-loop synchronous mode on channel layer
INFO:daphne.server:Listening on endpoint tcp:port=8000:interface=127.0.0.1
WARNING:django.request:Not Found: /accounts/static/doodles.png
WARNING:django.request:Not Found: /accounts/static/doodles.png
WARNING:django.request:Not Found: /accounts/static/doodles.png
WARNING:django.request:Not Found: /portal/
INFO:daphne.server:HTTP/2 support not enabled (install the http2 and tls Twisted extras)
INFO:daphne.server:Using busy-loop synchronous mode on channel layer
INFO:daphne.server:Listening on endpoint tcp:port=8000:interface=127.0.0.1
WARNING:django.request:Not Found: /portal/
INFO:daphne.server:HTTP/2 support not enabled (install the http2 and tls Twisted extras)
INFO:daphne.server:Using busy-loop synchronous mode on channel layer
INFO:daphne.server:Listening on endpoint tcp:port=8000:interface=127.0.0.1
INFO:daphne.server:HTTP/2 support not enabled (install the http2 and tls Twisted extras)
INFO:daphne.server:Using busy-loop synchronous mode on channel layer
INFO:daphne.server:Listening on endpoint tcp:port=8000:interface=127.0.0.1
INFO:daphne.server:HTTP/2 support not enabled (install the http2 and tls Twisted extras)
INFO:daphne.server:Using busy-loop synchronous mode on channel layer
INFO:daphne.server:Listening on endpoint tcp:port=8000:interface=127.0.0.1
INFO:daphne.server:HTTP/2 support not enabled (install the http2 and tls Twisted extras)
INFO:daphne.server:Using busy-loop synchronous mode on channel layer
INFO:daphne.server:Listening on endpoint tcp:port=8000:interface=127.0.0.1
INFO:daphne.server:HTTP/2 support not enabled (install the http2 and tls Twisted extras)
INFO:daphne.server:Using busy-loop synchronous mode on channel layer
INFO:daphne.server:Listening on endpoint tcp:port=8000:interface=127.0.0.1
